Workbook

Sheet Company Summary
A2: Executive Summary
A4: COMPANY: | B4: Sterling Infrastructure, Inc. | C4: ** NASDAQ: STRL
A5: SECTOR: | B5: Infrastructure
A6: TEAM: | B6: Anuja ,Kalaiiarasi, Prachi, Devadharshini
A7: RECOMMENDATION: | B7: NOT BUY
A8: ANALYSIS DATE | B8: Nov. 08.2025
A10: Investment
A12: Sterling Infrastructure represents a compelling growth opportunity, positioned at the intersection of massive government infrastructure spending and explosive data center demand.
A13: With exceptional financial performance, a rock-solid balance sheet, and record backlog, STRL is ideally positioned for sustained growth and value creation.
A15: Key Investment Highlights
A17: Exceptional Financial Performance
A19: 85.7% Net Income Growth ($258M) on 7.3% revenue growth
A20: Operating Cash Flow: $497M demonstrating strong cash generation
A21: Margin Expansion: Gross margin improved from 17.1% to 20.1%
A23: Superior Financial Health
A25: Liquidity: Current Ratio 1.38 with $664M cash (+40.9%)
A26: Leverage: Debt-to-Equity improved to 0.38 (from 0.55)
A27: Equity Growth: Stockholders' equity +32.5% to $826M
... A35: Financial Snapshot
A37: Metric | B37: 2023 | C37: 2024 | D37: Change
A39: Revenue | B39: $1.97B | C39: $2.12B | D39: 0.073
A40: Net Income | B40: $139M | C40: $258M | D40: 0.857
A41: Operating Cash Flow | B41: $479M | C41: $497M | D41: 0.039
A42: Current Ratio | B42: 1.25 | C42: 1.38 | D42: 0.104
A44: Debt-to-Equity | B44: 0.55 | C44: 0.38 | D44: -0.309
A46: Dividend Policy
A48: The company follows a zero-dividend policy. Strategy: Instead of paying dividends, Sterling Infrastructure reinvests all of its earnings to fund growth, reduce debt, and pursue strategic acquisitions. This is a common strategy for companies in a high-growth phase, focusing on capital appreciation for shareholders rather than providing income.
A50: Conclusion
A51: Sterling Infrastructure demonstrates powerful operational leverage, disciplined capital management, and strategic positioning in high-growth infrastructure markets.

Sheet Data Input Financial Statements
A1: Financial Statements | B1: (audited)
L2: CONDENSED CONSOLIDATED STATEMENTS OF OPERATIONS | N2: Data in thousands (000's)
C3: INCOME STATEMENT DATA | F3: Data in thousands (000's) | L3: (Unaudited)
A4: 0
B5: S.no. | C5: Line Item | D5: 2024 | E5: 2023 | F5: 2022 | G5: 2021 | H5: 2020 | I5: 2019 | K5: S.no. | L5: Line Item | M5: Three Months Ended Sept 30, 2025 | N5: Three Months Ended Sept 30, 2024 | O5: Nine Months Ended Sept 30, 2025 | P5: Nine Months Ended Sept 30, 2024
B6: 1 | C6: Revenues | D6: 2115756 | E6: 1972229 | F6: 1769436 | G6: 1414374 | H6: 1226738 | I6: 1126278 | K6: 1 | L6: Revenues | M6: 689019 | N6: 593741 | O6: 1734436 | P6: 1616923
B7: 2 | C7: Cost of Revenues | D7: -1689633 | E7: -1634591 | F7: -1494869 | G7: -1210842 | H7: -1047108 | I7: -1018484 | K7: 2 | L7: Cost of Revenues | M7: -518803 | N7: -463942 | O7: -1326240 | P7: -1297477
B8: 3 | C8: Gross Profit | D8: 426123 | E8: 337638 | F8: 274567 | G8: 203532 | H8: 179630 | I8: 107794 | K8: 3 | L8: Gross Profit | M8: 170216 | N8: 129799 | O8: 408196 | P8: 319446
B9: 4 | C9: General and Administrative Expense | D9: -118424 | E9: -98703 | F9: -86480 | G9: -69153 | H9: -64308 | I9: -49200 | K9: 4 | L9: General and Administrative Expense | M9: -37585 | N9: -30672 | O9: -106203 | P9: -85826
B10: 5 | C10: Intangible Asset Amortization | D10: -17037 | E10: -15229 | F10: -14100 | G10: -11464 | H10: -11436 | I10: -4695 | K10: 5 | L10: Intangible Asset Amortization | M10: -6035 | N10: -4280 | O10: -15074 | P10: -12857
B11: 6 | C11: Acquisition Related Costs | D11: -421 | E11: -873 | F11: -827 | G11: -3877 | H11: -1026 | I11: -4311 | K11: 6 | L11: Acquisition Related Costs | M11: -5349 | N11: -72 | O11: -8023 | P11: -209
B12: 7 | C12: Other Operating Expense, net | D12: -25619 | E12: -17041 | F12: -13290 | G12: -12027 | H12: -10245 | I12: -11837 | K12: 7 | L12: Earn-out expense | M12: -1343 | N12: -1000 | O12: -4029 | P12: -3000
B13: 8 | C13: Operating Income | D13: 264622 | E13: 205795 | F13: 159870 | G13: 107011 | H13: 92615 | I13: 37751 | K13: 8 | L13: Other Operating Expense, net | M13: 5405 | N13: -6283 | O13: 11082 | P13: -15203
B14: 9 | C14: Interest Income | D14: 27622 | E14: 14140 | F14: 885 | G14: 45 | H14: 149 | I14: 1142 | K14: 9 | L14: Operating Income | M14: 125309 | N14: 87492 | O14: 285949 | P14: 202351
B15: 10 | C15: Interest Expense | D15: -25255 | E15: -29320 | F15: -20591 | G15: -19311 | H15: -29332 | I15: -16686 | K15: 10 | L15: Interest Income | M15: 5677 | N15: 7591 | O15: 19405 | P15: 19798
B16: 11 | C16: Gain on Deconsolidation of Subsidiary, net | D16: 91289 | E16: - | F16: - | G16: 1064 | H16: -301 | I16: -7728 | K16: 11 | L16: Interest Expense | M16: -4140 | N16: -6286 | O16: -14367 | P16: -19463
B17: 12 | C17: Income Before Income Taxes | D17: 358278 | E17: 190615 | F17: 140164 | G17: 88809 | H17: 63131 | I17: 14479 | K17: 12 | L17: Income Before Income Taxes | M17: 126846 | N17: 88797 | O17: 290987 | P17: 202686
B18: 13 | C18: Income Tax Expense | D18: -87360 | E18: -47770 | F18: -41707 | G18: -24874 | H18: -19410 | I18: -26216 | K18: 13 | L18: Income Tax Expense | M18: -30517 | N18: -23404 | O18: -72959 | P18: -48960
B19: 14 | C19: Net Income (Including Noncontrolling Interests) | D19: 270918 | E19: 142845 | F19: 98457 | G19: 63935 | H19: 43721 | I19: 40695 | K19: 14 | L19: Net Income (Including Noncontrolling Interests) | M19: 96329 | N19: 65393 | O19: 218028 | P19: 153726
B20: 15 | C20: Less: Net Income Attributable to Noncontrolling Interests | D20: -13457 | E20: -4190 | F20: -1740 | G20: -2478 | H20: -598 | I20: -794 | K20: 15 | L20: Less: Net Income Attributable to Noncontrolling Interests | M20: -4241 | N20: -4072 | O20: -15472 | P20: -9478
B21: 16 | C21: Net Income from Continuing Operations | D21: 257461 | E21: 138655 | F21: 96717 | G21: 61457 | H21: 43123 | I21: 39901 | K21: 16 | L21: Net income attributable to Sterling common stockholders | M21: 92088 | N21: 61321 | O21: 202556 | P21: 144248
B22: 17 | C22: Earnings Per Share (EPS) - Basic | D22: 8.35 | E22: 4.51 | F22: 3.2 | G22: 2.15 | H22: 1.55 | I22: 1.5 | K22: 17 | L22: Earnings Per Share (EPS) - Basic | M22: 3.02 | N22: 2 | O22: 6.64 | P22: 4.67
B23: 18 | C23: Earnings Per Share (EPS) - Diluted | D23: 8.27 | E23: 4.44 | F23: 3.16 | G23: 2.11 | H23: 1.53 | I23: 1.47 | K23: 18 | L23: Earnings Per Share (EPS) - Diluted | M23: 2.97 | N23: 1.97 | O23: 6.56 | P23: 4.63
C26: BALANCE SHEET DATA
E27: `
C28: Line Item | D28: 2024 | E28: 2023 | F28: 2022 | G28: 2021 | H28: 2020 | I28: 2019
C29: ASSETS
C30: Current Assets
C31: Cash and Cash Equivalents | D31: 664195 | E31: 471563 | F31: 181544 | G31: 81840 | H31: 66185 | I31: 45733
C32: Accounts Receivable | D32: 247000 | E32: 252435 | F32: 262646 | G32: 232153 | H32: 177424 | I32: 248247
C33: Contract Assets | D33: 55387 | E33: 88600 | F33: 109803 | G33: 83310 | H33: 84975 | I33: 42555
C34: Receivables from and Equity in Construction Joint Ventures | D34: 5811 | E34: 17506 | F34: 14122 | G34: 16896 | H34: 16653 | I34: 9196
C35: Other Current Assets | D35: 17583 | E35: 17875 | F35: 29139 | G35: 20492 | H35: 16306 | I35: 11790
C36: Total Current Assets | D36: 1021880 | E36: 847979 | F36: 597254 | G36: 434691 | H36: 361543 | I36: 357521
C37: Property & Equipment, net | D37: 235795 | E37: 243448 | F37: 215482 | G37: 204316 | H37: 126668 | I37: 116030
C39: Goodwill | D39: 264597 | E39: 281117 | F39: 262692 | G39: 258290 | H39: 192014 | I39: 191892
C40: Other Intangibles, net | D40: 315390 | E40: 328397 | F40: 299123 | G40: 303223 | H40: 244887 | I40: 256323
C41: Other Non-Current Assets | D41: 17048 | E41: 18808 | F41: 7654 | G41: 4455 | H41: 3250 | I41: 40174
C42: Total Assets | D42: 2016774 | E42: 1777184 | F42: 1441620 | G42: 1230996 | H42: 952694 | I42: 961940
C44: LIABILITIES AND EQUITY
...

Sheet Liquidity Ratios
A1: Liquidity Ratios | D1: 2020-2024
A3: Purpose: To assess STRL's ability to meet its short-term obligations.
A5: Ratio | B5: Formula | C5: 2024 | D5: 2023 | E5: 2022 | F5: 2021 | G5: 2020 | H5: Interpretation (from analysis)
A7: Current Ratio | B7: Current Assets / Current Liabilities | C7: ='Data Input Financial Statements'!D36/'Data Input Financial Statements'!D50 -> 1.3772747 | D7: ='Data Input Financial Statements'!E36/'Data Input Financial Statements'!E50 -> 1.2503967 | E7: ='Data Input Financial Statements'!F36/'Data Input Financial Statements'!F50 -> 1.3373025 | F7: ='Data Input Financial Statements'!G36/'Data Input Financial Statements'!G50 -> 1.2357602 | G7: ='Data Input Financial Statements'!H36/'Data Input Financial Statements'!H50 -> 1.123209 | H7: The company’s ability to cover short-term liabilities with current assets increased steadily from 2020 (1.12) to 2024 (1.38).
A8: Quick Ratio | B8: Cash + Acc. Receivable) / Current Liabilities | C8: =(('Data Input Financial Statements'!D31+'Data Input Financial Statements'!D32))/'Data Input Financial Statements'!D50 -> 1.2280951 | D8: =(('Data Input Financial Statements'!E31+'Data Input Financial Statements'!E32))/'Data Input Financial Statements'!E50 -> 1.0675791 | E8: =(('Data Input Financial Statements'!F31+'Data Input Financial Statements'!F32))/'Data Input Financial Statements'!F50 -> 0.99457918 | F8: =(('Data Input Financial Statements'!G31+'Data Input Financial Statements'!G32))/'Data Input Financial Statements'!G50 -> 0.89263418 | G8: =(('Data Input Financial Statements'!H31+'Data Input Financial Statements'!H32))/'Data Input Financial Statements'!H50 -> 0.75682233 | H8: The Quick Ratio showed a notable improvement, rising from 0.76 in 2020 to 1.23 in 2024, reflecting the company’s better liquidity without relying on inventory sales.
A9: Cash Ratio | B9: Cash / Current Liabilities | C9: ='Data Input Financial Statements'!D31/'Data Input Financial Statements'!D50 -> 0.89519218 | D9: ='Data Input Financial Statements'!E31/'Data Input Financial Statements'!E50 -> 0.69534835 | E9: ='Data Input Financial Statements'!F31/'Data Input Financial Statements'!F50 -> 0.40649245 | F9: ='Data Input Financial Statements'!G31/'Data Input Financial Statements'!G50 -> 0.23265863 | G9: ='Data Input Financial Statements'!H31/'Data Input Financial Statements'!H50 -> 0.20561755 | H9: The Cash Ratio improved dramatically, climbing from 0.21 in 2020 to 0.90 in 2024, which suggests a much stronger cash position relative to liabilities.
H12: Overall
H13: The company's financial health has progressively improved from 2020 to 2024.
H14: The increase in liquidity ratios signals a more stable financial position, with stronger cash reserves and a better capacity to meet short-term liabilities.
H15: This puts the company in a favorable position moving forward, with minimized financial risk and a solid base for continued stability.

Sheet Leverage (Solvency Ratio)
A1: Leverage (Solvency) Ratios | F1: 2020-2024
A3: Purpose: To evaluate the company's financial structure and its ability to meet long-term debts.
E6: 2025 - Till September
B7: Ratio | C7: Formula | D7: 2023 | E7: 2025 | F7: Interpretation
B8: Debt-to-Equity | C8: Total liabilities / Total stockholder's Equity | E8: =1477272/1084995 -> 1.3615473 | F8: Over a five-year period, the leverage ratios are decreasing as the year progresses which is good sign that indicates that the co. is reducing its reliance on debt and strengthening equity financing.
B9: Debt-to-Assets | C9: Total liabilities / Total Assets | E9: =1477272/2562267 -> 0.57654881
B10: Equity Ratio | C10: Total stockholder's Equity / Total Assets | E10: =1084995/2562267 -> 0.42345119
B12: Ratio | C12: Formula | D12: 2023 | E12: 2024 | F12: 2023 | G12: 2022 | H12: Interpretation
B13: Debt-to-Equity | C13: Total liabilities / Total stockholder's Equity | E13: ='Data Input Financial Statements'!D52/'Data Input Financial Statements'!D53 -> 1.4402029 | F13: ='Data Input Financial Statements'!E52/'Data Input Financial Statements'!E53 -> 1.8487224 | G13: ='Data Input Financial Statements'!F52/'Data Input Financial Statements'!F53 -> 2.0172102 | H13: A clear drop over 3-yr period had been seen in the leverage ratio which indicates that co. is reducing its reliance on debt.
B14: Debt-to-Assets | C14: Total liabilities / Total Assets | E14: ='Data Input Financial Statements'!D52/'Data Input Financial Statements'!D42 -> 0.59019801 | F14: ='Data Input Financial Statements'!E52/'Data Input Financial Statements'!E42 -> 0.64896544 | G14: ='Data Input Financial Statements'!F52/'Data Input Financial Statements'!F42 -> 0.668568 | H14: The overall decrease over years shows a smaller portion of the company’s assets is financed by debt, indicating a healthier balance sheet and less vulnerability to interest rate shifts or financial distress
B15: Equity Ratio | C15: Total stockholder's Equity / Total Assets | E15: ='Data Input Financial Statements'!D53/'Data Input Financial Statements'!D42 -> 0.40980199 | F15: ='Data Input Financial Statements'!E53/'Data Input Financial Statements'!E42 -> 0.35103456 | G15: ='Data Input Financial Statements'!F53/'Data Input Financial Statements'!F42 -> 0.331432 | H15: The increase reveals the company’s asset base is increasingly financed through equity, and it has strengthened its capital position.
B18: Note : Total debt = | C18: Current Portion of Long-term Debt + Long-term Debt
B22: Ratio | C22: Formula | D22: 2023 | E22: 2021 | F22: 2020 | G22: 2019
B23: Debt-to-Equity | C23: Total liabilities / Total stockholder's Equity | E23: ='Data Input Financial Statements'!G52/'Data Input Financial Statements'!G53 -> 2.4172785 | F23: ='Data Input Financial Statements'!H52/'Data Input Financial Statements'!H53 -> 2.5451849 | G23: ='Data Input Financial Statements'!I52/'Data Input Financial Statements'!I53 -> 3.3485179
B24: Debt-to-Assets | C24: Total liabilities / Total Assets | E24: ='Data Input Financial Statements'!G52/'Data Input Financial Statements'!G42 -> 0.70736948 | F24: ='Data Input Financial Statements'!H52/'Data Input Financial Statements'!H42 -> 0.71792727 | G24: ='Data Input Financial Statements'!I52/'Data Input Financial Statements'!I42 -> 0.77003659
B25: Equity Ratio | C25: Total stockholder's Equity / Total Assets | E25: ='Data Input Financial Statements'!G53/'Data Input Financial Statements'!G42 -> 0.29263052 | F25: ='Data Input Financial Statements'!H53/'Data Input Financial Statements'!H42 -> 0.28207273 | G25: ='Data Input Financial Statements'!I53/'Data Input Financial Statements'!I42 -> 0.22996341
A30: Years | B30: Debt-to-Equity | C30: Debt-to-Assets | D30: Equity Ratio
A31: 2019 | B31: 3.35 | C31: 0.77 | D31: 0.23
A32: 2020 | B32: 2.55 | C32: 0.72 | D32: 0.28
A33: 2021 | B33: 2.42 | C33: 0.71 | D33: 0.29
A34: 2022 | B34: 2.02 | C34: 0.67 | D34: 0.33
A35: 2023 | B35: 1.85 | C35: 0.65 | D35: 0.35
A36: 2024 | B36: 1.44 | C36: 0.59 | D36: 0.41
A37: 2025 | B37: 1.36 | C37: 0.58 | D37: 0.42

Sheet EBITDA
A1: EBITDA Calculation ($ in thousands)
A3: ITEMS | B3: 2024 | C3: 2023 | D3: 2022 | E3: 2021 | F3: 2020
A5: Operating Income | B5: 264622 | C5: 205795 | D5: 159870 | E5: 107011 | F5: 92615
A6: Depreciation & Amortization | B6: 68410 | C6: 57403 | D6: 52066 | E6: $34,201 | F6: 32785
A7: EBITDA | B7: =SUM(B5:B6) -> 333032 | C7: =SUM(C5:C6) -> 263198 | D7: =SUM(D5:D6) -> 211936 | E7: 141212 | F7: =SUM(F5:F6) -> 125400

Sheet Efficiency (Activity Ratio)
A1: Efficiency (Activity) Ratios
A3: Purpose: To measure how effectively the company utilizes its assets and manages its operations.
A4: Note: "Average" values (e.g., (2023 Value + 2024 Value)/2). Sales data is from the Income Statement.
E6: 2023-2024
B8: Ratio | C8: Formula | D8: 2023 | E8: 2024 | F8: Interpretation
B9: Asset Turnover | C9: Sales / Average Total Assets | E9: ='Data Input Financial Statements'!D6/'Efficiency (Activity Ratio)'!F15 -> 1.1153292 | F9: High, Products are in high demand and the company manages its stock expertly, minimizing wasted capital.
B10: Receivables Turnover | C10: Credit Sales / Average Acc. Receivable | E10: ='Data Input Financial Statements'!D6/'Efficiency (Activity Ratio)'!F16 -> 8.472598 | F10: High. The company collects receivables every 43 days, indicating excellent collection efficiency.
B11: Accounts Payable Turnover | C11: Supplier Purchases / Average Acc. Payable | E11: =-'Data Input Financial Statements'!D7/F17 -> 11.966748 | F11: Moderate. The company pays suppliers every 30 days, showing balanced payment terms.
B13: Note :
B15: Average total assets = | C15: (Begining Total Assets "2023"+ Ending Total Assets"2024")/2 | F15: =(('Data Input Financial Statements'!E42+'Data Input Financial Statements'!D42))/2 -> 1896979
B16: Average Acc. Receivable= | C16: (Begining Acc. Rec "2023"+ Ending Acc. Rec "2024")/2 | F16: =(('Data Input Financial Statements'!E32+'Data Input Financial Statements'!D32))/2 -> 249717.5
B17: Average Acc. Payable= | C17: (Begining Acc. Payable"2023"+ Ending Acc. Payable "2024")/2 | F17: =(('Data Input Financial Statements'!E46+'Data Input Financial Statements'!D46))/2 -> 141194
A18: (Use for tab Profitabilty Ratio) | B18: Average Shareholder Equity = | C18: (Begining Shareholder Equity"2023"+ Ending Shareholder Equity "2024")/2 | F18: =(('Data Input Financial Statements'!E53+'Data Input Financial Statements'!D53))/2 -> 725165.5
B20: Credit Sales = Revenue
B21: 1. Credit sales not available, total revenue used instead. company like Sterling Infra (B2B) does sales on credit and minimum usage of cash.
B22: 2. Standard accounting practice when credit sales not available , may understate ratio ( conservative approach)
B24: Supplier Purchase= | C24: Cost of revenue - Other direct costs
F26: Overall
F27: The company is excellent at using its assets to generate sales and managing its working capital.
E30: 2022-2023
B32: Ratio | C32: Formula | D32: 2023 | E32: 2023 | F32: Interpretation
B33: Asset Turnover | C33: Sales / Average Total Assets | E33: ='Data Input Financial Statements'!E6/'Efficiency (Activity Ratio)'!F40 -> 1.2254421 | F33: Strong performance, remains efficient despite slight decrease from 2022.
B34: Receivables Turnover | C34: Credit Sales / Average Acc. Receivable | E34: ='Data Input Financial Statements'!E6/'Efficiency (Activity Ratio)'!F41 -> 7.6579373 | F34: Maintaining excellent collection efficiency.
B35: Accounts Payable Turnover | C35: Supplier Purchases / Average Acc. Payable | E35: =-'Data Input Financial Statements'!E7/F42 -> 12.205044 | F35: Showing consistent and disciplined working capital management.
B38: Note :
B40: Average total assets = | C40: (Begining Total Assets "2022"+ Ending Total Assets"2023")/2 | F40: =(('Data Input Financial Statements'!F42+'Data Input Financial Statements'!E42))/2 -> 1609402
B41: Average Acc. Receivable= | C41: (Begining Acc. Rec "2022"+ Ending Acc. Rec "2023")/2 | F41: =(('Data Input Financial Statements'!F32+'Data Input Financial Statements'!E32))/2 -> 257540.5
B42: Average Acc. Payable= | C42: (Begining Acc. Payable"2022"+ Ending Acc. Payable "2023")/2 | F42: =(('Data Input Financial Statements'!F46+'Data Input Financial Statements'!E46))/2 -> 133927.5
B43: Average Shareholder Equity = | C43: (Begining Shareholder Equity"2022"+ Ending Shareholder Equity "2023")/2 | F43: =(('Data Input Financial Statements'!F53+'Data Input Financial Statements'!E53))/2 -> 550826
E46: 2021-2022
B48: Ratio | C48: Formula | D48: 2023 | E48: 2022 | F48: Interpretation
B49: Asset Turnover | C49: Sales / Average Total Assets | E49: ='Data Input Financial Statements'!F6/'Efficiency (Activity Ratio)'!F57 -> 1.3241229 | F49: Outstanding revenue generation from assets — $1.32 in sales per $1 of assets, indicating peak operational efficiency.
B50: Receivables Turnover | C50: Credit Sales / Average Acc. Receivable | E50: ='Data Input Financial Statements'!F6/'Efficiency (Activity Ratio)'!F58 -> 7.1521406 | F50: Collected receivables , reflecting a highly efficient credit and collection process.
B51: Accounts Payable Turnover | C51: Supplier Purchases / Average Acc. Payable | E51: =-'Data Input Financial Statements'!F7/F59 -> 11.203017 | F51: Paid suppliers every , showing skillful cash flow management and strong supplier relationships.
B55: *Note :
B57: Average total assets = | C57: (Begining Total Assets "2021"+ Ending Total Assets"2022")/2 | F57: =(('Data Input Financial Statements'!G42+'Data Input Financial Statements'!F42))/2 -> 1336308
B58: Average Acc. Receivable= | C58: (Begining Acc. Rec "2021"+ Ending Acc. Rec "2022")/2 | F58: =(('Data Input Financial Statements'!G32+'Data Input Financial Statements'!F32))/2 -> 247399.5
B59: Average Acc. Payable= | C59: (Begining Acc. Payable"2021"+ Ending Acc. Payable "2022")/2 | F59: =(('Data Input Financial Statements'!G46+'Data Input Financial Statements'!F46))/2 -> 133434.5
B60: Average Shareholder Equity = | C60: (Begining Shareholder Equity"2021"+ Ending Shareholder Equity "2022")/2 | F60: =(('Data Input Financial Statements'!G53+'Data Input Financial Statements'!F53))/2 -> 419013
E63: 2020-2021
...

Sheet Profitabilty Ratio
A1: Profitability Ratios | F1: 2024-2020
A3: Purpose: To assess the company's ability to generate earnings relative to sales, assets, and equity.
B5: Ratio : Gross Profit Margin, Operating Profit Margin and Net Profit Margin
B7: Ratio | C7: Formula | D7: 2023 | E7: 2024 | F7: 2023 | G7: 2022 | H7: 2021 | I7: 2020 | J7: Interpretation
B8: Gross Profit Margin | C8: Gross Profit / Sales | E8: ='Data Input Financial Statements'!D8/'Data Input Financial Statements'!D6 -> 0.2014046 | F8: ='Data Input Financial Statements'!E8/'Data Input Financial Statements'!E6 -> 0.17119614 | G8: ='Data Input Financial Statements'!F8/'Data Input Financial Statements'!F6 -> 0.15517204 | H8: ='Data Input Financial Statements'!G8/'Data Input Financial Statements'!G6 -> 0.14390253 | I8: ='Data Input Financial Statements'!H8/'Data Input Financial Statements'!H6 -> 0.14642898 | J8: Improved, indicating better control over production costs and stronger pricing power. For 2022,Indicates moderate profitability, suggesting limited control over production or input costs.
B9: Operating Profit Margin | C9: Operating Income / Sales | E9: ='Data Input Financial Statements'!D13/'Data Input Financial Statements'!D6 -> 0.12507208 | F9: ='Data Input Financial Statements'!E13/'Data Input Financial Statements'!E6 -> 0.1043464 | G9: ='Data Input Financial Statements'!F13/'Data Input Financial Statements'!F6 -> 0.090350824 | H9: ='Data Input Financial Statements'!G13/'Data Input Financial Statements'!G6 -> 0.07565962 | I9: ='Data Input Financial Statements'!H13/'Data Input Financial Statements'!H6 -> 0.075496968 | J9: Increased, showing enhanced efficiency in managing operating expenses. For 2022,Shows modest operational efficiency with room to reduce operating expenses.
B10: Net Profit Margin | C10: Net Income / Sales | E10: ='Data Input Financial Statements'!D21/'Data Input Financial Statements'!D6 -> 0.12168747 | F10: ='Data Input Financial Statements'!E21/'Data Input Financial Statements'!E6 -> 0.070303702 | G10: ='Data Input Financial Statements'!F21/'Data Input Financial Statements'!F6 -> 0.05465979 | H10: ='Data Input Financial Statements'!G21/'Data Input Financial Statements'!G6 -> 0.043451732 | I10: ='Data Input Financial Statements'!H21/'Data Input Financial Statements'!H6 -> 0.035152575 | J10: Strengthened, reflecting higher overall profitability and effective cost management. For 2022, Reflects low overall profitability, implying higher costs or lower revenue retention after all expenses.
B13: Ratio : Return of Assets and Return on Equity
B15: Ratio | C15: Formula | D15: 2023 | E15: 2024 | G15: Interpretation
B16: Return on Assets (ROA) | C16: Net Income / Average Total Assets | E16: ='Data Input Financial Statements'!D21/'Efficiency (Activity Ratio)'!F15 -> 0.13572159 | G16: Asset utilization was more effective and maximized profit
B17: Return on Equity (ROE) | C17: Net Income / Average Shareholders' Equity | E17: ='Data Input Financial Statements'!D21/'Efficiency (Activity Ratio)'!F18 -> 0.35503757 | G17: Achieved highest return compared to other years. Shareholders gained more valye and this reflects strong performance and financial health.
B20: Ratio | C20: Formula | D20: 2023 | E20: 2023 | G20: Interpretation
B21: Return on Assets (ROA) | C21: Net Income / Average Total Assets | E21: ='Data Input Financial Statements'!E21/'Efficiency (Activity Ratio)'!F40 -> 0.086153118 | G21: Made better use of assets, reflecting higher productivity and profitability
B22: Return on Equity (ROE) | C22: Net Income / Average Shareholders' Equity | E22: ='Data Input Financial Statements'!E21/'Efficiency (Activity Ratio)'!F43 -> 0.25172196 | G22: The return to shareholders rose further, showing strong profit growth.
B24: Ratio | C24: Formula | D24: 2023 | E24: 2022 | G24: Interpretation
B25: Return on Assets (ROA) | C25: Net Income / Average Total Assets | E25: ='Data Input Financial Statements'!F21/'Efficiency (Activity Ratio)'!F57 -> 0.072376279 | G25: There is a improvement in asset efficiency, Better usage of resource and indicates strong operational control.
B26: Return on Equity (ROE) | C26: Net Income / Average Shareholders' Equity | E26: ='Data Input Financial Statements'!F21/'Efficiency (Activity Ratio)'!F60 -> 0.230821 | G26: Increase in profitability for shareholders. Managed equity more efficiently than 2021.
B29: Ratio | C29: Formula | D29: 2023 | E29: 2021 | G29: Interpretation
B30: Return on Assets (ROA) | C30: Net Income / Average Total Assets | E30: ='Data Input Financial Statements'!G21/'Efficiency (Activity Ratio)'!F74 -> 0.056287294 | G30: Moderate improvement in asset utilization. The company used its asset base more efficiently than in 2020, reflecting stronger operational execution and better cost management.
B31: Return on Equity (ROE) | C31: Net Income / Average Shareholders' Equity | E31: ='Data Input Financial Statements'!G21/'Efficiency (Activity Ratio)'!F77 -> 0.19542544 | G31: Shareholder returns increased, showing improved profitability. Equity was deployed more effectively, indicating rising earnings power and stronger financial performance.
B33: Ratio | C33: Formula | D33: 2023 | E33: 2020 | G33: Interpretation
B34: Return on Assets (ROA) | C34: Net Income / Average Total Assets | E34: ='Data Input Financial Statements'!H21/'Efficiency (Activity Ratio)'!F94 -> 0.045045685 | G34: Asset efficiency was modest. The company generated moderate profit from its assets, reflecting cautious operations during a challenging economic year.
B35: Return on Equity (ROE) | C35: Net Income / Average Shareholders' Equity | E35: ='Data Input Financial Statements'!H21/'Efficiency (Activity Ratio)'!F97 -> 0.1760338 | G35: Shareholders earned solid returns, indicating effective use of equity capital. Despite external challenges, the company maintained respectable profitability and stable financial management.

Sheet Market Value Ratio
A1: Market Value Ratios
A3: Purpose: To gauge the market's perception of the company's future prospects and valuation.
D4: 2024
A6: Ratio | B6: Formula | C6: Calculation | D6: 2024 | E6: Interpretation
A7: Earnings Per Share (EPS) - Basic | B7: Given | C7: Given | D7: ='Data Input Financial Statements'!D22 -> 8.35 | E7: The P/E ratio expanded significantly to 21.26, indicating that investors were willing to pay over $21 for every $1 of earnings.
A8: Price-to-Earnings (P/E) Ratio | B8: Share Price / EPS | C8: $177.51/ $8.35 | D8: ='Data Input Financial Statements'!D77/'Data Input Financial Statements'!D22 -> 21.258683
A9: Dividend Payout Ratio | B9: Total Dividends / Net Income | C9: $0 / $257,461,000 | D9: =0/'Data Input Financial Statements'!D21 -> 0
A10: Dividend Yield | B10: Dividend per Share / Share Price | C10: $0 / $177.51 | D10: =0/'Data Input Financial Statements'!D77 -> 0
B12: *Share price : Dec 2024 ( refer data input tab)
D14: 2023
A16: Ratio | B16: Formula | C16: Calculation | D16: 2023 | E16: Interpretation
A17: Earnings Per Share (EPS) - Basic | B17: Given | C17: Given | D17: ='Data Input Financial Statements'!E22 -> 4.51 | E17: The P/E ratio of 19.50 shows a healthy level of investor confidence, a substantial increase from the previous year.
A18: Price-to-Earnings (P/E) Ratio | B18: Share Price / EPS | C18: $87.93/$4.51 | D18: ='Data Input Financial Statements'!E77/'Data Input Financial Statements'!E22 -> 19.496674
A19: Dividend Payout Ratio | B19: Total Dividends / Net Income | C19: 0/$138,655 | D19: =0/'Data Input Financial Statements'!E21 -> 0
A20: Dividend Yield | B20: Dividend per Share / Share Price | C20: 0/$87.93 | D20: =0/'Data Input Financial Statements'!E77 -> 0
D22: 2022
A24: Ratio | B24: Formula | C24: Calculation | D24: 2022 | E24: Interpretation
A25: Earnings Per Share (EPS) - Basic | B25: Given | C25: Given | D25: ='Data Input Financial Statements'!F22 -> 3.2 | E25: A P/E ratio of 10.25 suggests the market had a more conservative valuation of the company.
A26: Price-to-Earnings (P/E) Ratio | B26: Share Price / EPS | C26: $32.80/$3.20 | D26: ='Data Input Financial Statements'!F77/'Data Input Financial Statements'!F22 -> 10.25
A27: Dividend Payout Ratio | B27: Total Dividends / Net Income | C27: 0/$96,717 | D27: 0
A28: Dividend Yield | B28: Dividend per Share / Share Price | C28: 0/$32.80 | D28: 0
D31: 2021
A33: Ratio | B33: Formula | C33: Calculation | D33: 2021 | E33: Interpretation
A34: Earnings Per Share (EPS) - Basic | B34: Given | C34: Given | D34: ='Data Input Financial Statements'!G22 -> 2.15 | E34: The P/E ratio increased to 12.23, reflecting a slightly more optimistic market valuation compared to 2020, potentially due to improving earnings. The company maintained its zero-dividend policy, continuing to reinvest all profits back into the business.
A35: Price-to-Earnings (P/E) Ratio | B35: Share Price / EPS | C35: $26.3/$2.15 | D35: ='Data Input Financial Statements'!G77/'Data Input Financial Statements'!G22 -> 12.232558
A36: Dividend Payout Ratio | B36: Total Dividends / Net Income | C36: 0/$61,457 | D36: =0/'Data Input Financial Statements'!G21 -> 0
A37: Dividend Yield | B37: Dividend per Share / Share Price | C37: 0/$26.3 | D37: =0/'Data Input Financial Statements'!G77 -> 0
D43: 2020
A45: Ratio | B45: Formula | C45: Calculation | D45: 2020 | E45: Interpretation
A46: Earnings Per Share (EPS) - Basic | B46: Given | C46: Given | D46: 1.55 | E46: The P/E ratio of 12.01 indicates a moderate market valuation. The company's consistent zero-dividend payout across all three years confirms a strategic focus on using retained earnings to fund growth and operations rather than providing shareholder income.
A47: Price-to-Earnings (P/E) Ratio | B47: Share Price / EPS | C47: $18.61/$1.55 | D47: ='Data Input Financial Statements'!H77/'Data Input Financial Statements'!H22 -> 12.006452
A48: Dividend Payout Ratio | B48: Total Dividends / Net Income | C48: 0/$43,123 | D48: 0
A49: Dividend Yield | B49: Dividend per Share / Share Price | C49: 0/$18.61 | D49: 0

Sheet Altman z score+ Dupont Analysis
A1: Altman Z score + Dupont Analysis
B3: Altman Z score
B5: Ratio | C5: Formula | D5: 2024 | E5: 2023 | F5: 2022 | G5: 2021 | H5: 2020 | I5: Interpretation
B6: Altman Z score | C6: Z=1.2*X1​+1.4*X2​+3.3*X3​+0.6*X4​+1.0*X5​ | D6: =1.2*D10+1.4*D11+3.3*D12+0.6*D13+1*D14 -> 5.0092532 | E6: =1.2*E10+1.4*E11+3.3*E12+0.6*E13+1*E14 -> 3.771402 | F6: =1.2*F10+1.4*F11+3.3*F12+0.6*F13+1*F14 -> 2.8068288 | G6: =1.2*G10+1.4*G11+3.3*G12+0.6*G13+1*G14 -> 2.4537289 | H6: =1.2*H10+1.4*H11+3.3*H12+0.6*H13+1*H14 -> 2.5136075 | I6: Indicates low risk of bankruptcy and strong financial stability
B8: Notes
B9: Variable | C9: Formula | D9: 2024 | E9: 2023 | F9: 2022 | G9: 2021 | H9: 2020 | I9: Meaning
B10: X1 | C10: Working Capital / Total Assets | D10: =('Data Input Financial Statements'!D36-'Data Input Financial Statements'!D50)/'Data Input Financial Statements'!D42 -> 0.13879691 | E10: =('Data Input Financial Statements'!E36-'Data Input Financial Statements'!E51)/'Data Input Financial Statements'!E42 -> 0.3004084 | F10: =('Data Input Financial Statements'!F36-'Data Input Financial Statements'!F50)/'Data Input Financial Statements'!F42 -> 0.10449564 | G10: =('Data Input Financial Statements'!G36-'Data Input Financial Statements'!G50)/'Data Input Financial Statements'!G42 -> 0.067369025 | H10: =('Data Input Financial Statements'!H36-'Data Input Financial Statements'!H50)/'Data Input Financial Statements'!H42 -> 0.041628267 | I10: Measures liquidity
B11: X2 | C11: Retained Earnings / Total Assets | D11: ='Data Input Financial Statements'!D53/'Data Input Financial Statements'!D42 -> 0.40980199 | E11: ='Data Input Financial Statements'!E53/'Data Input Financial Statements'!E42 -> 0.35103456 | F11: ='Data Input Financial Statements'!F53/'Data Input Financial Statements'!F42 -> 0.331432 | G11: ='Data Input Financial Statements'!G53/'Data Input Financial Statements'!G42 -> 0.29263052 | H11: ='Data Input Financial Statements'!H53/'Data Input Financial Statements'!H42 -> 0.28207273 | I11: Measures profitability over time
B12: X3 | C12: EBIT / Total Assets | D12: ='Data Input Financial Statements'!D13/'Data Input Financial Statements'!D42 -> 0.13121054 | E12: ='Data Input Financial Statements'!E13/'Data Input Financial Statements'!E42 -> 0.11579836 | F12: ='Data Input Financial Statements'!F13/'Data Input Financial Statements'!F42 -> 0.11089608 | G12: ='Data Input Financial Statements'!G13/'Data Input Financial Statements'!G42 -> 0.086930421 | H12: ='Data Input Financial Statements'!H13/'Data Input Financial Statements'!H42 -> 0.097213796 | I12: Measures operating efficiency
B13: X4 | C13: Market Value of Equity / Total Liabilities | D13: ='Data Input Financial Statements'!D75*'Data Input Financial Statements'!D77/'Data Input Financial Statements'!D52 -> 4.6448333 | E13: ='Data Input Financial Statements'!E75*'Data Input Financial Statements'!E77/'Data Input Financial Statements'!E52 -> 2.3792991 | F13: ='Data Input Financial Statements'!F75*'Data Input Financial Statements'!F77/'Data Input Financial Statements'!F52 -> 1.0401301 | G13: ='Data Input Financial Statements'!G75*'Data Input Financial Statements'!G77/'Data Input Financial Statements'!G52 -> 0.87894298 | H13: ='Data Input Financial Statements'!H75*'Data Input Financial Statements'!H77/'Data Input Financial Statements'!H52 -> 0.7671576 | I13: Measures leverage or solvency
B14: X5 | C14: Sales / Total Assets | D14: ='Data Input Financial Statements'!D6/'Data Input Financial Statements'!D42 -> 1.0490794 | E14: ='Data Input Financial Statements'!E6/'Data Input Financial Statements'!E42 -> 1.1097495 | F14: ='Data Input Financial Statements'!F6/'Data Input Financial Statements'!F42 -> 1.2273942 | G14: ='Data Input Financial Statements'!G6/'Data Input Financial Statements'!G42 -> 1.1489672 | H14: ='Data Input Financial Statements'!H6/'Data Input Financial Statements'!H42 -> 1.2876516 | I14: Measures asset turnover (efficiency)
B17: Dupont Analysis
C19: 3 STEP MODEL | D19: 2024 | E19: 2023 | F19: 2022 | G19: 2021 | H19: 2020
C21: Net Profit Margin(NPM)= Net income/ revenue | D21: ='Data Input Financial Statements'!D21/'Data Input Financial Statements'!D6 -> 0.12168747 | E21: ='Data Input Financial Statements'!E21/'Data Input Financial Statements'!E6 -> 0.070303702 | F21: ='Data Input Financial Statements'!F21/'Data Input Financial Statements'!F6 -> 0.05465979 | G21: ='Data Input Financial Statements'!G21/'Data Input Financial Statements'!G6 -> 0.043451732 | H21: ='Data Input Financial Statements'!H21/'Data Input Financial Statements'!H6 -> 0.035152575
C22: Asset Turnover(AT)= Revenue/Total Assets | D22: ='Data Input Financial Statements'!D6/'Data Input Financial Statements'!D42 -> 1.0490794 | E22: ='Data Input Financial Statements'!E6/'Data Input Financial Statements'!E42 -> 1.1097495 | F22: ='Data Input Financial Statements'!F6/'Data Input Financial Statements'!F42 -> 1.2273942 | G22: ='Data Input Financial Statements'!G6/'Data Input Financial Statements'!G42 -> 1.1489672 | H22: ='Data Input Financial Statements'!H6/'Data Input Financial Statements'!H42 -> 1.2876516
C23: Equity Multiplier(EM)= Total Assets/Equity | D23: ='Data Input Financial Statements'!D42/'Data Input Financial Statements'!D53 -> 2.4402029 | E23: ='Data Input Financial Statements'!E42/'Data Input Financial Statements'!E53 -> 2.8487224 | F23: ='Data Input Financial Statements'!F42/'Data Input Financial Statements'!F53 -> 3.0172102 | G23: ='Data Input Financial Statements'!G42/'Data Input Financial Statements'!G53 -> 3.4172785 | H23: ='Data Input Financial Statements'!H42/'Data Input Financial Statements'!H53 -> 3.5451849
C24: ROE= NPM*AT*EM | D24: =D21*D22*D23 -> 0.31151585 | E24: =E21*E22*E23 -> 0.22225588 | F24: =F21*F22*F23 -> 0.20242194 | G24: =G21*G22*G23 -> 0.17060631 | H24: =H21*H22*H23 -> 0.16047021
C27: 5 STEP MODEL | D27: 2024 | E27: 2023 | F27: 2022 | G27: 2021 | H27: 2020
C28: Tax burden= Net Income/ EBT | D28: ='Data Input Financial Statements'!D21/'Data Input Financial Statements'!D17 -> 0.71860678 | E28: ='Data Input Financial Statements'!E21/'Data Input Financial Statements'!E17 -> 0.72740865 | F28: ='Data Input Financial Statements'!F21/'Data Input Financial Statements'!F17 -> 0.6900274 | G28: ='Data Input Financial Statements'!G21/'Data Input Financial Statements'!G17 -> 0.6920132 | H28: ='Data Input Financial Statements'!H21/'Data Input Financial Statements'!H17 -> 0.68307171
C29: Interest Burden=EBT/EBIT | D29: ='Data Input Financial Statements'!D17/'Data Input Financial Statements'!D13 -> 1.3539237 | E29: ='Data Input Financial Statements'!E17/'Data Input Financial Statements'!E13 -> 0.92623727 | F29: ='Data Input Financial Statements'!F17/'Data Input Financial Statements'!F13 -> 0.87673735 | G29: ='Data Input Financial Statements'!G17/'Data Input Financial Statements'!G13 -> 0.82990534 | H29: ='Data Input Financial Statements'!H17/'Data Input Financial Statements'!H13 -> 0.68164984
C30: EBIT Margin= EBIT/Revenue | D30: ='Data Input Financial Statements'!D13/'Data Input Financial Statements'!D6 -> 0.12507208 | E30: ='Data Input Financial Statements'!E13/'Data Input Financial Statements'!E6 -> 0.1043464 | F30: ='Data Input Financial Statements'!F13/'Data Input Financial Statements'!F6 -> 0.090350824 | G30: ='Data Input Financial Statements'!G13/'Data Input Financial Statements'!G6 -> 0.07565962 | H30: ='Data Input Financial Statements'!H13/'Data Input Financial Statements'!H6 -> 0.075496968
C31: Asset Turnover(AT)= Revenue/Total Assets | D31: ='Data Input Financial Statements'!D6/'Data Input Financial Statements'!D42 -> 1.0490794 | E31: ='Data Input Financial Statements'!E6/'Data Input Financial Statements'!E42 -> 1.1097495 | F31: ='Data Input Financial Statements'!F6/'Data Input Financial Statements'!F42 -> 1.2273942 | G31: ='Data Input Financial Statements'!G6/'Data Input Financial Statements'!G42 -> 1.1489672 | H31: ='Data Input Financial Statements'!H6/'Data Input Financial Statements'!H42 -> 1.2876516
C32: Equity Multiplier(EM)= Total Assets/Equity | D32: ='Data Input Financial Statements'!D42/'Data Input Financial Statements'!D53 -> 2.4402029 | E32: ='Data Input Financial Statements'!E42/'Data Input Financial Statements'!E53 -> 2.8487224 | F32: ='Data Input Financial Statements'!F42/'Data Input Financial Statements'!F53 -> 3.0172102 | G32: ='Data Input Financial Statements'!G42/'Data Input Financial Statements'!G53 -> 3.4172785 | H32: ='Data Input Financial Statements'!H42/'Data Input Financial Statements'!H53 -> 3.5451849
C33: ROE | D33: =D28*D29*D30*D31*D32 -> 0.31151585 | E33: =E28*E29*E30*E31*E32 -> 0.22225588 | F33: =F28*F29*F30*F31*F32 -> 0.20242194 | G33: =G28*G29*G30*G31*G32 -> 0.17060631 | H33: =H28*H29*H30*H31*H32 -> 0.16047021
C36: YEAR | D36: ROE | E36: Interpretation
C37: 2020 | D37: 0.16 | E37: ROE indicates the company delivered strong profitability relative to the equity invested by shareholders.
C38: 2021 | D38: 0.17 | E38: ROE reflects a slight improvement in how efficiently the company used shareholder equity to generate profits.
C39: 2022 | D39: 0.2 | E39: ROE mainly driven by high leverage. Profit margins were low, so the company relied more on debt to generate returns.
C40: 2023 | D40: 0.22 | E40: ROE grew due to high operating profitability with moderate efficiency and leverage. Interest cost impact reduced, helping net profit.
C41: 2024 | D41: 0.31 | E41: ROE surged mainly because of higher profitability, boosted by one-time gains. Leverage decreased but efficiency remained stable. Taxes and interesr had smaller relative impact

Sheet Ratio Graphs
A1: Liquidity Ratios
B2: 2020 | C2: 2021 | D2: 2022 | E2: 2023 | F2: 2024 | G2: Trend
A3: Current Ratio | B3: 1.12 | C3: 1.24 | D3: 1.34 | E3: 1.25 | F3: 1.38 | G3: Improving
A4: Quick Ratio | B4: 0.76 | C4: 0.89 | D4: 1 | E4: 1.07 | F4: 1.23 | G4: Strong improvement
A5: Cash Ratio | B5: 0.21 | C5: 0.23 | D5: 0.42 | E5: 0.7 | F5: 0.9 | G5: Excellent
A7: Leverage (Solvency) Ratios
B8: 2020 | C8: 2021 | D8: 2022 | E8: 2023 | F8: 2024 | G8: Trend
A9: Debt-to-Equity* | B9: 1.37 | C9: 1.27 | D9: 0.9 | E9: 0.55 | F9: 0.38 | G9: Decreasing (Positive)
A10: Debt-to-Assets* | B10: 0.72 | C10: 0.71 | D10: 0.67 | E10: 0.65 | F10: 0.59 | G10: Decreasing
A11: Equity Ratio* | B11: 0.28 | C11: 0.29 | D11: 0.33 | E11: 0.35 | F11: 0.41 | G11: Increasing
A14: Efficiency (Activity) Ratios
B15: 2020 | C15: 2021 | D15: 2022 | E15: 2023 | F15: 2024 | G15: Interpretation
A16: Asset Turnover | B16: 1.3 | C16: 1.3 | D16: 1.32 | E16: 1.23 | F16: 1.11 | G16: High asset utilization
A17: Receivables Turnover | B17: 6.91 | C17: 6.91 | D17: 7.16 | E17: 7.63 | F17: 8.46 | G17: Excellent collection efficiency
A18: Accounts Payable Turnover | B18: 10.08 | C18: 10.08 | D18: 11.03 | E18: 11.5 | F18: 12.08 | G18: Moderate payment terms
A20: Profitability Ratios
B21: 2020 | C21: 2021 | D21: 2022 | E21: 2023 | F21: 2024 | G21: Trend
A22: Gross Profit Margin | B22: 0.146 | C22: 0.144 | D22: 0.155 | E22: 0.171 | F22: 0.201 | G22: Strong improvement
A23: Operating Profit Margin | B23: 0.076 | C23: 0.076 | D23: 0.09 | E23: 0.104 | F23: 0.125 | G23: Improving efficiency
A24: Net Profit Margin | B24: 0.035 | C24: 0.043 | D24: 0.055 | E24: 0.07 | F24: 0.122 | G24: Exceptional growth
A25: Return on Assets (ROA) | B25: 0.045 | C25: 0.05 | D25: 0.067 | E25: 0.078 | F25: 0.128 | G25: Outstanding
A26: Return on Equity (ROE) | B26: 0.16 | C26: 0.171 | D26: 0.202 | E26: 0.222 | F26: 0.312 | G26: Excellent
A29: Market Value Ratios
B30: 2020 | C30: 2021 | D30: 2022 | E30: 2023 | F30: 2024 | G30: Interpretation
A31: EPS - Basic | B31: 1.55 | C31: 2.15 | D31: 3.2 | E31: 4.51 | F31: 8.35 | G31: Strong growth
A32: P/E Ratio | B32: 12.01 | C32: 12.23 | D32: 10.25 | E32: 19.5 | F32: 21.26 | G32: Increasing valuation
A33: Dividend Payout Ratio | B33: 0 | C33: 0 | D33: 0 | E33: 0 | F33: 0 | G33: Zero dividend policy
A34: Dividend Yield | B34: 0 | C34: 0 | D34: 0 | E34: 0 | F34: 0 | G34: Reinvestment strategy
A37: Advanced Analysis
B38: 2020 | C38: 2021 | D38: 2022 | E38: 2023 | F38: 2024 | G38: Interpretation
A39: Altman Z-Score | B39: 2.62 | C39: 2.75 | D39: 2.97 | E39: 3.36 | F39: 4.32 | G39: Low bankruptcy risk
A40: EBITDA ($k) | B40: 125400 | C40: 141212 | D40: 211936 | E40: 263198 | F40: 333032 | G40: Strong growth
A41: ROE (DuPont) | B41: 0.16 | C41: 0.17 | D41: 0.2 | E41: 0.22 | F41: 0.31 | G41: Improving returns
A44: Key Ratios
B45: 2023 | C45: 2024 | D45: Change
A46: Current Ratio | B46: 1.25 | C46: 1.38 | D46: 0.104
A47: Debt-to-Equity | B47: 0.55 | C47: 0.38 | D47: -0.309
A48: Gross Margin | B48: 0.171 | C48: 0.201 | D48: +3.0pp
A49: Operating Cash Flow | B49: $479M | C49: $497M | D49: 0.039
A52: Solvency ratios
...

Sheet  DCF Valuation 
A1: DCF Valuation
B2: 2020 | C2: 2021 | D2: 2022 | E2: 2023 | F2: 2024 | G2: 2025E | H2: 2026E | I2: 2027E | J2: 2028E | K2: 2029E
A3: Revenues | B3: 1226738 | C3: 1414374 | D3: 1769436 | E3: 1972229 | F3: 2115756 | G3: =F3*(1+G4) -> 2327331.6 | H3: =G3*(1+H4) -> 2560064.8 | I3: =H3*(1+I4) -> 2816071.2 | J3: =I3*(1+J4) -> 3097678.4 | K3: =J3*(1+K4) -> 3407446.2
C4: =(C3-B3)/B3 -> 0.15295524 | D4: =(D3-C3)/C3 -> 0.25103827 | E4: =(E3-D3)/D3 -> 0.11460884 | F4: =(F3-E3)/E3 -> 0.072774003 | G4: 0.1 | H4: 0.1 | I4: 0.1 | J4: 0.1 | K4: 0.1 | M4: Assumption 1: Sterling’s revenue is expected to grow 10% each year due to strong E-Infrastructure demand and federal infrastructure spending.
A5: Cost of Revenues | B5: -1047108 | C5: -1210842 | D5: -1494869 | E5: -1634591 | F5: -1689633 | G5: =F5*(1+G6) -> -1791011 | H5: =G5*(1+H6) -> -1880561.5 | I5: =H5*(1+I6) -> -1955784 | J5: =I5*(1+J6) -> -2014457.5 | K5: =J5*(1+K6) -> -2054746.7
C6: =(C5-B5)/B5 -> 0.15636782 | D6: =(D5-C5)/C5 -> 0.23456983 | E6: =(E5-D5)/D5 -> 0.093467722 | F6: =(F5-E5)/E5 -> 0.033673255 | G6: 0.06 | H6: 0.05 | I6: 0.04 | J6: 0.03 | K6: 0.02
A7: Gross Profit | B7: =B3+B5 -> 179630 | C7: =C3+C5 -> 203532 | D7: =D3+D5 -> 274567 | E7: =E3+E5 -> 337638 | F7: =F3+F5 -> 426123 | G7: =G3+G5 -> 536320.62 | H7: =H3+H5 -> 679503.23 | I7: =I3+I5 -> 860287.25 | ... K7: =K3+K5 -> 1352699.5
C8: =(C7-B7)/B7 -> 0.13306241 | D8: =(D7-C7)/C7 -> 0.34901146 | E8: =(E7-D7)/D7 -> 0.22971078 | F8: =(F7-E7)/E7 -> 0.26207062 | G8: =(G7-F7)/F7 -> 0.25860519 | H8: =(H7-G7)/G7 -> 0.26697204 | I8: =(I7-H7)/H7 -> 0.26605321 | J8: =(J7-I7)/I7 -> 0.25913857 | K8: =(K7-J7)/J7 -> 0.24877539
A9: General and Administrative Expense | B9: -64308 | C9: -69153 | D9: -86480 | E9: -98703 | F9: -118424 | G9: =F9*(1+G10) -> -124345.2 | H9: =G9*(1+H10) -> -130562.46 | I9: =H9*(1+I10) -> -135784.96 | J9: =I9*(1+J10) -> -139858.51 | K9: =J9*(1+K10) -> -144054.26
C10: =(C9-B9)/B9 -> 0.075340549 | D10: =(D9-C9)/C9 -> 0.25056035 | E10: =(E9-D9)/D9 -> 0.14133904 | F10: =(F9-E9)/E9 -> 0.19980142 | G10: =5% -> 0.05 | H10: =5% -> 0.05 | I10: =4% -> 0.04 | J10: =3% -> 0.03 | K10: =3% -> 0.03
A11: Intangible Asset Amortization | B11: -11436 | C11: -11464 | D11: -14100 | E11: -15229 | F11: -17037 | G11: =F11*(1+G12) -> -17377.74 | H11: =G11*(1+H12) -> -17725.295 | I11: =H11*(1+I12) -> -18079.801 | J11: =I11*(1+J12) -> -18441.397 | K11: =J11*(1+K12) -> -18810.225
C12: =(C11-B11)/B11 -> 0.0024484085 | D12: =(D11-C11)/C11 -> 0.22993719 | E12: =(E11-D11)/D11 -> 0.080070922 | F12: =(F11-E11)/E11 -> 0.11872086 | G12: =2% -> 0.02 | H12: =2% -> 0.02 | I12: =2% -> 0.02 | J12: =2% -> 0.02 | K12: =2% -> 0.02
A13: Acquisition Related Costs | B13: -1026 | C13: -3877 | D13: -827 | E13: -873 | F13: -421 | G13: -421 | H13: -421 | I13: -421 | J13: -421 | K13: -421
A14: Other Operating Expense, net | B14: -10245 | C14: -12027 | D14: -13290 | E14: -17041 | F14: -25619 | G14: -25619 | H14: -25619 | I14: -25619 | J14: -25619 | K14: -25619
C15: =(C14-B14)/B14 -> 0.17393851 | D15: =(D14-C14)/C14 -> 0.10501372 | E15: =(E14-D14)/D14 -> 0.28224229 | F15: =(F14-E14)/E14 -> 0.50337422 | G15: =(G14-F14)/F14 -> 0 | H15: =(H14-G14)/G14 -> 0 | I15: =(I14-H14)/H14 -> 0 | J15: =(J14-I14)/I14 -> 0 | K15: =(K14-J14)/J14 -> 0
A16: Operating Income | B16: 92615 | C16: 107011 | D16: 159870 | E16: 205795 | F16: 264622 | G16: =G7+G9+G11+G13+G14 -> 368557.68 | H16: =H7+H9+H11+H13+H14 -> 505175.48 | I16: =I7+I9+I11+I13+I14 -> 680382.49 | J16: =J7+J9+J11+J13+J14 -> 898880.95 | K16: =K7+K9+K11+K13+K14 -> 1163795
C17: =(C16-B16)/B16 -> 0.15543918 | D17: =(D16-C16)/C16 -> 0.49395857 | E17: =(E16-D16)/D16 -> 0.28726465 | F17: =(F16-E16)/E16 -> 0.28585243 | G17: =(G16-F16)/F16 -> 0.39277037 | H17: =(H16-G16)/G16 -> 0.37068227 | I17: =(I16-H16)/H16 -> 0.34682406 | J17: =(J16-I16)/I16 -> 0.32114063 | K17: =(K16-J16)/J16 -> 0.29471545
A18: Interest Income | B18: 149 | C18: 45 | D18: 885 | E18: 14140 | F18: 27622 | G18: =F18*(1+G19) -> 29003.1 | H18: =G18*(1+H19) -> 30453.255 | I18: =H18*(1+I19) -> 31975.918 | J18: =I18*(1+J19) -> 33574.714 | K18: =J18*(1+K19) -> 35253.449
C19: =(C18-B18)/B18 -> -0.69798658 | D19: =(D18-C18)/C18 -> 18.666667 | E19: =(E18-D18)/D18 -> 14.977401 | F19: =(F18-E18)/E18 -> 0.95346535 | G19: =5% -> 0.05 | H19: =5% -> 0.05 | I19: =5% -> 0.05 | J19: =5% -> 0.05 | K19: =5% -> 0.05
A20: Interest Expense | B20: -29332 | C20: -19311 | D20: -20591 | E20: -29320 | F20: -25255 | G20: =F20*(1+G21) -> -24749.9 | H20: =G20*(1+H21) -> -24254.902 | I20: =H20*(1+I21) -> -23769.804 | J20: =I20*(1+J21) -> -23294.408 | K20: =J20*(1+K21) -> -22828.52
C21: =(C20-B20)/B20 -> -0.34164053 | D21: =(D20-C20)/C20 -> 0.066283465 | E21: =(E20-D20)/D20 -> 0.42392307 | F21: =(F20-E20)/E20 -> -0.13864256 | G21: =-2% -> -0.02 | H21: =-2% -> -0.02 | I21: =-2% -> -0.02 | J21: =-2% -> -0.02 | K21: =-2% -> -0.02
A22: Gain on Deconsolidation of Subsidiary, net | B22: -301 | C22: 1064 | D22: - | E22: - | F22: 91289
A23: Income Before Income Taxes | B23: 63131 | C23: 88809 | D23: 140164 | E23: 190615 | F23: 358278
A24: Income Tax Expense | B24: -19410 | C24: -24874 | D24: -41707 | E24: -47770 | F24: -87360
A25: Net Income (Including Noncontrolling Interests) | B25: 43721 | C25: 63935 | D25: 98457 | E25: 142845 | F25: 270918 | G25: =F25*(1+G4) -> 298009.8 | H25: =G25*(1+H4) -> 327810.78 | I25: =H25*(1+I4) -> 360591.86 | J25: =I25*(1+J4) -> 396651.04 | K25: =J25*(1+K4) -> 436316.15
C26: =(C25-B25)/B25 -> 0.46234075 | D26: =(D25-C25)/C25 -> 0.53995464 | E26: =(E25-D25)/D25 -> 0.45083641 | F26: =(F25-E25)/E25 -> 0.89658721
A27: Less: Net Income Attributable to Noncontrolling Interests | B27: -598 | C27: -2478 | D27: -1740 | E27: -4190 | F27: -13457
C28: =(C27-B27)/B27 -> 3.1438127 | D28: =(D27-C27)/C27 -> -0.29782082 | E28: =(E27-D27)/D27 -> 1.408046 | F28: =(F27-E27)/E27 -> 2.2116945
A29: Net Income from Continuing Operations | B29: 43123 | C29: 61457 | D29: 96717 | E29: 138655 | F29: 257461 | G29: =F29*(1+G4) -> 283207.1 | H29: =G29*(1+H4) -> 311527.81 | I29: =H29*(1+I4) -> 342680.59 | J29: =I29*(1+J4) -> 376948.65 | K29: =J29*(1+K4) -> 414643.52
C30: =(C29-B29)/B29 -> 0.42515595 | D30: =(D29-C29)/C29 -> 0.57373448 | E30: =(E29-D29)/D29 -> 0.4336156 | F30: =(F29-E29)/E29 -> 0.85684613
A31: Depreciation and Amortization | B31: 32785 | C31: 34201 | D31: 52066 | E31: 57403 | F31: 68410
C32: =(C31-B31)/B31 -> 0.043190483 | D32: =(D31-C31)/C31 -> 0.52235315 | E32: =(E31-D31)/D31 -> 0.10250451 | F32: =(F31-E31)/E31 -> 0.19174956
A33: EBITDA | B33: =B16+B31 -> 125400 | C33: =C16+C31 -> 141212 | D33: =D16+D31 -> 211936 | E33: =E16+E31 -> 263198 | F33: =F16+F31 -> 333032
C34: =(C33-B33)/B33 -> 0.1260925 | D34: =(D33-C33)/C33 -> 0.50083562 | E34: =(E33-D33)/D33 -> 0.24187491 | F34: =(F33-E33)/E33 -> 0.26532876
A35: Depreciation and Amortization | B35: 32785 | C35: 34201 | D35: 52066 | E35: 57403 | F35: 68410 | G35: =F35*(1+G36) -> 75251 | H35: =G35*(1+H36) -> 82776.1 | I35: =H35*(1+I36) -> 91053.71 | J35: =I35*(1+J36) -> 100159.08 | K35: =J35*(1+K36) -> 110174.99
C36: =(C35-B35)/B35 -> 0.043190483 | D36: =(D35-C35)/C35 -> 0.52235315 | E36: =(E35-D35)/D35 -> 0.10250451 | F36: =(F35-E35)/E35 -> 0.19174956 | G36: =10% -> 0.1 | H36: =10% -> 0.1 | I36: =10% -> 0.1 | J36: =10% -> 0.1 | K36: =10% -> 0.1 | M36: Assumption 2: Depreciation grows 10% annually, consistent with Sterling’s increasing CAPEX requirements for equipment and infrastructure.
A37: Interest Expense | B37: 29332 | C37: 19311 | D37: 20591 | E37: 29320 | F37: 25255 | G37: =F37*(1+G38) -> 24749.9 | H37: =G37*(1+H38) -> 24254.902 | I37: =H37*(1+I38) -> 23769.804 | J37: =I37*(1+J38) -> 23294.408 | K37: =J37*(1+K38) -> 22828.52
C38: =(C37-B37)/B37 -> -0.34164053 | D38: =(D37-C37)/C37 -> 0.066283465 | E38: =(E37-D37)/D37 -> 0.42392307 | F38: =(F37-E37)/E37 -> -0.13864256 | G38: =-2% -> -0.02 | H38: =-2% -> -0.02 | I38: =-2% -> -0.02 | J38: =-2% -> -0.02 | K38: =-2% -> -0.02 | M38: Assumption 3: Interest expense declines 2% per year, reflecting decreasing leverage and improving credit position.
A39: Tax Rate | B39: =-B24/B23 -> 0.30745592 | C39: =-C24/C23 -> 0.28008423 | D39: =-D24/D23 -> 0.29755857 | E39: =-E24/E23 -> 0.25060987 | F39: =-F24/F23 -> 0.243833 | G39: =0.28 -> 0.28 | H39: =G39+H40 -> 0.285 | I39: =H39+I40 -> 0.285 | J39: =I39+J40 -> 0.283 | K39: =J39+K40 -> 0.28
G40: =1% -> 0.01 | H40: =0.5% -> 0.005 | I40: =0% -> 0 | J40: =-0.2% -> -0.002 | K40: -0.003 | M40: Assumption 4: Tax rate gradually converges toward 28.5%, with yearly adjustments of ±1%, based on historical stability.
...

Sheet Discount Rate 2024 (WACC)
A3: CAPM: | B3: =risk-free + Beta * (Equity Risk Premium) | D3: Barrons | E3: =C6+C7*C9 -> 0.10229691
A4: CAPM: | B4: =risk-free + Beta * (Equity Risk Premium) | D4: Yahoo.Finance | E4: =C6+C8*C9 -> 0.10489491
A6: (Most recent) | B6: Risk-free | C6: ='10-yr BOND YEILD'!H1 -> 0.040810909 | E6: https://www.investing.com/rates-bonds/u.s.-10-year-bond-yield-historical-data
B7: Beta | C7: 1.42 | E7: https://www.barrons.com/market-data/stocks/strl?mod=quotes_search
B8: Beta | C8: 1.48 | E8: https://finance.yahoo.com/quote/STRL/
B9: Equity Risk Premium | C9: 0.0433 | E9: https://pages.stern.nyu.edu/~adamodar/New_Home_Page/datafile/ctryprem.html
A13: WACC: | B13: =D*(1-t)*rd/(E+D)+E*re/(E+D) | D13: =C15*(1-C16)*C17/(C19+C15)+C19*C20/(C15+C19) -> 0.092455708
B15: Debt (D) | C15: =289898+26423 -> 316321 | D15: (Long term debt+current maturity of long term debt)
B16: Tax rate (t) effective | C16: 0.24
B17: Cost of debt (rd) | C17: =C25/C24 -> 0.079839783
B19: Equity (E) | C19: 808081 | D19: (Sterling's stockholder's equity)
B20: Cost of equity (re)=CAPM | C20: =E4 -> 0.10489491
A24: ** | B24: Total interest bearing debt | C24: =26423+289898 -> 316321
A25: ** | B25: Interest expense | C25: 25255

Sheet DiscounT Rate 2025 (WACC)
A2: CAPM: | B2: =risk-free + Beta * (Equity Risk Premium) | D2: Barrons | E2: =C5+C6*C8 -> 0.10229691
A3: CAPM: | B3: =risk-free + Beta * (Equity Risk Premium) | D3: Yahoo.Finance | E3: =C5+C7*C8 -> 0.10489491
A5: (Most recent) | B5: Risk-free | C5: ='10-yr BOND YEILD'!H1 -> 0.040810909 | E5: https://www.investing.com/rates-bonds/u.s.-10-year-bond-yield-historical-data
B6: Beta | C6: 1.42 | E6: https://www.barrons.com/market-data/stocks/strl?mod=quotes_search
B7: Beta | C7: 1.48 | E7: https://finance.yahoo.com/quote/STRL/
B8: Equity Risk Premium | C8: 0.0433 | E8: https://pages.stern.nyu.edu/~adamodar/New_Home_Page/datafile/ctryprem.html
A12: WACC: | B12: =D*(1-t)*rd/(E+D)+E*re/(E+D) | D12: =C14*(1-C15)*C16/(C18+C14)+C18*C19/(C14+C18) -> 0.092888523
A14: 2025 unaudited data figures estimation | B14: Debt (D) | C14: =279479+15154 -> 294633 | D14: (Long term debt+current maturity of long term debt)
A15: https://www.sec.gov/ix?doc=/Archives/edgar/data/874238/000087423825000136/strl-20250930.htm#i31862837a4e34d98ad720a16217e8575_16 | B15: Tax rate (t) effective | C15: 0.24
B16: Cost of debt (rd) | C16: =C24/C23 -> 0.065861597
B18: Equity (E) | C18: 1051126 | D18: (Sterling's stockholder's equity)
B19: Cost of equity (re)=CAPM | C19: =E3 -> 0.10489491
A23: ** | B23: Total interest bearing debt | C23: =279479+15154 -> 294633
A24: ** | B24: Interest expense | C24: 19405
A27: - | B27: The business must earn at least 9.29% on new investments or projects to satisfy both lenders and shareholders, covering the cost of all forms of capital.
A28: - | B28: Only projects or investments generating returns greater than 9.25% truly add value to the firm; anything less may destroy value.
A29: - | B29: A WACC of 9.25% reflects the company’s overall risk and market environment. In construction and infrastructure, WACC between 8–10% is typical for healthy, established firms.
A30: - | B30: Used as the discount rate in DCF models. Cash flows discounted at 9.25% measure the present value of future operating profits.
A31: - | B31: The effective tax rate is the actual percentage of a company’s pre-tax income that is paid as income tax.

Sheet Terminal Value Calculation
B2: g | C2: 0.03
B3: TV | C3: =(' DCF Valuation '!K52*1.03)/(0.0925-0.03) -> 7402329.6
A5: The Terminal Value of 7,402.329.65 represents the present value of all cash flows beyond the forecast period, assuming a stable 3% growth. It reflects the long-term value of the company and forms a significant part of the total enterprise value.

Sheet 10-yr BOND YEILD
A1: Date | B1: Price | C1: Open | D1: High | E1: Low | F1: Change % | H1: =AVERAGE(B2:B23)/100 -> 0.040810909
A2: 45992 | B2: 4.095 | C2: 4.039 | D2: 4.102 | E2: 4.027 | F2: 0.0159
A3: 45991 | B3: 4.031 | C3: 4.027 | D3: 4.036 | E3: 4.027 | F3: 0.003
A4: 45989 | B4: 4.019 | C4: 4.008 | D4: 4.036 | E4: 3.961 | F4: 0.0035
A5: 45988 | B5: 4.005 | C5: 3.998 | D5: 4.015 | E5: 3.991 | F5: 0.0018
A6: 45987 | B6: 3.998 | C6: 4.004 | D6: 4.044 | E6: 3.99 | F6: -0.001
A7: 45986 | B7: 4.002 | C7: 4.031 | D7: 4.046 | E7: 3.988 | F7: -0.0084
A8: 45985 | B8: 4.036 | C8: 4.059 | D8: 4.069 | E8: 4.027 | F8: -0.0066
A9: 45982 | B9: 4.063 | C9: 4.092 | D9: 4.102 | E9: 4.036 | F9: -0.01
A10: 45981 | B10: 4.104 | C10: 4.146 | D10: 4.168 | E10: 4.084 | F10: -0.0065
A11: 45980 | B11: 4.131 | C11: 4.117 | D11: 4.141 | E11: 4.098 | F11: 0.0024
A12: 45979 | B12: 4.121 | C12: 4.146 | D12: 4.148 | E12: 4.084 | F12: -0.0029
A13: 45978 | B13: 4.133 | C13: 4.154 | D13: 4.158 | E13: 4.115 | F13: -0.0036
... A23: 45964 | B23: 4.107 | C23: 4.101 | D23: 4.122 | E23: 4.081 | F23: 0.0015

Sheet Present Value Calculation
A3: FCCF and Terminal Value Inputs | E3: Terminal Value | H3: Discounting TV to PV | L3: Discounting FCFF for 2025-2029 | R3: Sum for Enterprise Value | T3: Adjusting for Net Debt | X3: Intrinsic Value
A5: FCFF 2029 | C5: 449170000 | E5: =(C5*1.03)/(0.0925-0.03) -> 7402321600 | H5: PV(TV) | I5: =E5/(1+0.0925)^5 -> 4.7562067e+09 | J5: (Year 5 is 2029) | L5: 2025 | M5: 2026 | N5: 2027 | O5: 2028 | P5: 2029 | R5: Sum of PV (FCFF)+ PV(TV) | T5: Total debt(2024) | V5: 289898000 | X5: per share value
A6: WACC | C6: 0.0925 | L6: =' DCF Valuation '!G52*1000 -> 3.0384689e+08 | M6: =' DCF Valuation '!H52*1000 -> 3.3241979e+08 | N6: =' DCF Valuation '!I52*1000 -> 3.6694984e+08 | O6: =' DCF Valuation '!J52*1000 -> 4.1073836e+08 | P6: =' DCF Valuation '!K52*1000 -> 4.4917049e+08 | R6: =L12+I5 -> 6.1715167e+09 | T6: Cash (2024) | V6: 664195000 | X6: =V9/C8 -> 210.16547
A7: Perpetual growth | C7: 0.03 | K7: PV | L7: =277990*1000 -> 277990000 | M7: 278417000 | N7: 281819000 | O7: 288343000 | P7: 288741000 | T7: Net cash | V7: =V6-V5 -> 374297000
A8: Shares O/s (2024) | C8: 31146000 | X8: Current STRL price | Z8: 316.32
T9: Equity Value | V9: =R6+V7 -> 6.5458137e+09
K12: Total | L12: =SUM(L7:P7) -> 1415310000

Sheet Relative valuation
A3: Company | B3: Market Cap | C3: Enterprise Value (EV) | D3: Revenue | E3: EBITDA | F3: EPS | G3: EV/EBITDA | H3: P/E | I3: Size | J3: Stock price
A4: STRL | B4: 9.85 | C4: 9.93B | D4: 0.062 | E4: 0.3121 | F4: 2.57 | G4: 22.1 | H4: 28 | I4: Mid- cap | J4: -
A5: FLUOR CORP | B5: 6.83B | C5: 5.12B | D5: -0.0181 | E5: 1.2974 | F5: 0.37 | G5: 9.6 | H5: 20.25 | I5: Mid- cap | J5: 43.96
A6: PRIMORIS SERVICES CORP | B6: 6.67B | C6: 7.20B | D6: 0.2145 | E6: 0.4152 | F6: 0.98 | G6: 10.89 | H6: 22.98 | I6: Mid- cap | J6: 125.166
A7: BADGER INFRASTRUCTURE SOLUTIONS | B7: 1.76B | C7: 2.01B | D7: 0.1018 | E7: 0.103 | F7: 0.53 | G7: 12.07 | H7: 20.71 | I7: Small- cap | J7: 55.37
A8: DYCOM INDUSTRIES INC | B8: 10.14B | C8: 11.09B | D8: 0.1319 | E8: 0.2942 | F8: 1.7 | G8: 16.21 | H8: 26.85 | I8: Mid- cap | J8: 351.8
A9: GRANITE CONSTRUCTIONS INC | B9: 4.65B | C9: 5.55B | D9: 0.0687 | E9: 0.678 | F9: 1.47 | G9: 11.85 | H9: 17.54 | I9: Mid- cap | J9: 108.08
A10: MYR GROUP INC/DELAWARE | B10: 3.37B | C10: 3.41B | D10: -0.0064 | E10: 0.6647 | F10: 1.85 | G10: 15.21 | H10: 25.42 | I10: Small/Mid- cap | J10: 228.54
A12: MEDIAN (EV/EBITDA) | B12: =G14 -> 11.96 | F12: =F4*H12 -> 59.0586 | G12: 12.07 | H12: 22.98
A13: MEDIAN (PE) | B13: =H14 -> 21.845
A14: EBITDA OF STRL | B14: =E4*EBITDA!B7 -> 103939.29 | G14: =MEDIAN(G5:G10) -> 11.96 | H14: =MEDIAN(H5:H10) -> 21.845
A15: IMPLIED EV | B15: =G12*B14 -> 1254547.2
A16: IMPLIED PRICE - EV/EBITDA | B16: =1628844200/31146000 -> 52.297059
A17: IMPLIED SHARE PRICE - P/E | B17: =F4*B13 -> 56.14165
